[2021-01-19 14:00:59 +1000] [11836] [INFO] Starting gunicorn 20.0.4
[2021-01-19 14:00:59 +1000] [11836] [INFO] Listening at: unix:/run/gunicorn.sock (11836)
[2021-01-19 14:00:59 +1000] [11836] [INFO] Using worker: sync
[2021-01-19 14:00:59 +1000] [11839] [INFO] Booting worker with pid: 11839
[2021-01-19 14:00:59 +1000] [11840] [INFO] Booting worker with pid: 11840
[2021-01-19 14:00:59 +1000] [11841] [INFO] Booting worker with pid: 11841
[2021-01-19 16:16:35 +1000] [11839] [INFO] Worker exiting (pid: 11839)
[2021-01-19 16:16:35 +1000] [11840] [INFO] Worker exiting (pid: 11840)
[2021-01-19 16:16:35 +1000] [11841] [INFO] Worker exiting (pid: 11841)
[2021-01-19 16:16:35 +1000] [11836] [INFO] Handling signal: term
[2021-01-19 16:16:35 +1000] [11836] [INFO] Shutting down: Master
[2021-01-21 12:16:55 +1000] [28337] [INFO] Starting gunicorn 20.0.4
[2021-01-21 12:16:55 +1000] [28337] [INFO] Listening at: unix:/run/gunicorn.sock (28337)
[2021-01-21 12:16:55 +1000] [28337] [INFO] Using worker: sync
[2021-01-21 12:16:55 +1000] [28340] [INFO] Booting worker with pid: 28340
[2021-01-21 12:16:55 +1000] [28341] [INFO] Booting worker with pid: 28341
[2021-01-21 12:16:55 +1000] [28342] [INFO] Booting worker with pid: 28342
[2021-01-21 12:57:14 +1000] [28337] [INFO] Handling signal: term
[2021-01-21 12:57:14 +1000] [28341] [INFO] Worker exiting (pid: 28341)
[2021-01-21 12:57:14 +1000] [28342] [INFO] Worker exiting (pid: 28342)
[2021-01-21 12:57:14 +1000] [28340] [INFO] Worker exiting (pid: 28340)
[2021-01-21 12:57:15 +1000] [28337] [INFO] Shutting down: Master
[2021-01-21 12:57:16 +1000] [29698] [INFO] Starting gunicorn 20.0.4
[2021-01-21 12:57:16 +1000] [29698] [INFO] Listening at: unix:/run/gunicorn.sock (29698)
[2021-01-21 12:57:16 +1000] [29698] [INFO] Using worker: sync
[2021-01-21 12:57:16 +1000] [29701] [INFO] Booting worker with pid: 29701
[2021-01-21 12:57:16 +1000] [29702] [INFO] Booting worker with pid: 29702
[2021-01-21 12:57:16 +1000] [29703] [INFO] Booting worker with pid: 29703
[2021-01-21 13:16:14 +1000] [29698] [INFO] Handling signal: term
[2021-01-21 13:16:14 +1000] [29703] [INFO] Worker exiting (pid: 29703)
[2021-01-21 13:16:14 +1000] [29702] [INFO] Worker exiting (pid: 29702)
[2021-01-21 13:16:14 +1000] [29701] [INFO] Worker exiting (pid: 29701)
[2021-01-21 13:16:15 +1000] [29698] [INFO] Shutting down: Master
[2021-01-21 13:27:52 +1000] [30549] [INFO] Starting gunicorn 20.0.4
[2021-01-21 13:27:52 +1000] [30549] [INFO] Listening at: unix:/run/gunicorn.sock (30549)
[2021-01-21 13:27:52 +1000] [30549] [INFO] Using worker: sync
[2021-01-21 13:27:52 +1000] [30564] [INFO] Booting worker with pid: 30564
[2021-01-21 13:27:52 +1000] [30565] [INFO] Booting worker with pid: 30565
[2021-01-21 13:27:52 +1000] [30566] [INFO] Booting worker with pid: 30566
[2021-01-21 13:28:02 +1000] [30549] [INFO] Handling signal: term
[2021-01-21 13:28:02 +1000] [30564] [INFO] Worker exiting (pid: 30564)
[2021-01-21 13:28:02 +1000] [30566] [INFO] Worker exiting (pid: 30566)
[2021-01-21 13:28:02 +1000] [30565] [INFO] Worker exiting (pid: 30565)
[2021-01-21 13:28:02 +1000] [30549] [INFO] Shutting down: Master
[2021-01-21 13:28:43 +1000] [30652] [INFO] Starting gunicorn 20.0.4
[2021-01-21 13:28:43 +1000] [30652] [INFO] Listening at: unix:/run/gunicorn.sock (30652)
[2021-01-21 13:28:43 +1000] [30652] [INFO] Using worker: sync
[2021-01-21 13:28:43 +1000] [30666] [INFO] Booting worker with pid: 30666
[2021-01-21 13:28:43 +1000] [30667] [INFO] Booting worker with pid: 30667
[2021-01-21 13:28:43 +1000] [30670] [INFO] Booting worker with pid: 30670
[2021-01-21 14:53:17 +1000] [30670] [INFO] Worker exiting (pid: 30670)
[2021-01-21 14:53:17 +1000] [30666] [INFO] Worker exiting (pid: 30666)
[2021-01-21 14:53:17 +1000] [30652] [INFO] Handling signal: term
[2021-01-21 14:53:17 +1000] [30667] [INFO] Worker exiting (pid: 30667)
[2021-01-21 14:53:17 +1000] [30652] [INFO] Shutting down: Master
[2021-01-21 16:33:44 +1000] [4250] [INFO] Starting gunicorn 20.0.4
[2021-01-21 16:33:44 +1000] [4250] [INFO] Listening at: unix:/run/gunicorn.sock (4250)
[2021-01-21 16:33:44 +1000] [4250] [INFO] Using worker: sync
[2021-01-21 16:33:44 +1000] [4265] [INFO] Booting worker with pid: 4265
[2021-01-21 16:33:44 +1000] [4266] [INFO] Booting worker with pid: 4266
[2021-01-21 16:33:44 +1000] [4267] [INFO] Booting worker with pid: 4267
[2021-01-21 16:36:53 +1000] [4250] [INFO] Handling signal: term
[2021-01-21 16:36:53 +1000] [4266] [INFO] Worker exiting (pid: 4266)
[2021-01-21 16:36:53 +1000] [4265] [INFO] Worker exiting (pid: 4265)
[2021-01-21 16:36:53 +1000] [4267] [INFO] Worker exiting (pid: 4267)
[2021-01-21 16:36:53 +1000] [4250] [INFO] Shutting down: Master
[2021-01-22 13:47:28 +1000] [9971] [INFO] Starting gunicorn 20.0.4
[2021-01-22 13:47:28 +1000] [9971] [INFO] Listening at: unix:/run/gunicorn.sock (9971)
[2021-01-22 13:47:28 +1000] [9971] [INFO] Using worker: sync
[2021-01-22 13:47:28 +1000] [9987] [INFO] Booting worker with pid: 9987
[2021-01-22 13:47:28 +1000] [9988] [INFO] Booting worker with pid: 9988
[2021-01-22 13:47:28 +1000] [9991] [INFO] Booting worker with pid: 9991
[2021-01-22 13:50:23 +1000] [9971] [INFO] Handling signal: term
[2021-01-22 13:50:23 +1000] [9991] [INFO] Worker exiting (pid: 9991)
[2021-01-22 13:50:23 +1000] [9988] [INFO] Worker exiting (pid: 9988)
[2021-01-22 13:50:23 +1000] [9987] [INFO] Worker exiting (pid: 9987)
[2021-01-22 13:50:23 +1000] [9971] [INFO] Shutting down: Master
[2021-01-22 15:07:03 +1000] [18790] [INFO] Starting gunicorn 20.0.4
[2021-01-22 15:07:03 +1000] [18790] [INFO] Listening at: unix:/run/gunicorn.sock (18790)
[2021-01-22 15:07:03 +1000] [18790] [INFO] Using worker: sync
[2021-01-22 15:07:03 +1000] [18804] [INFO] Booting worker with pid: 18804
[2021-01-22 15:07:03 +1000] [18805] [INFO] Booting worker with pid: 18805
[2021-01-22 15:07:03 +1000] [18808] [INFO] Booting worker with pid: 18808
[2021-01-22 15:11:32 +1000] [18790] [INFO] Handling signal: term
[2021-01-22 15:11:32 +1000] [18808] [INFO] Worker exiting (pid: 18808)
[2021-01-22 15:11:32 +1000] [18805] [INFO] Worker exiting (pid: 18805)
[2021-01-22 15:11:32 +1000] [18804] [INFO] Worker exiting (pid: 18804)
[2021-01-22 15:11:33 +1000] [18790] [INFO] Shutting down: Master
[2021-01-22 15:11:38 +1000] [19566] [INFO] Starting gunicorn 20.0.4
[2021-01-22 15:11:38 +1000] [19566] [INFO] Listening at: unix:/run/gunicorn.sock (19566)
[2021-01-22 15:11:38 +1000] [19566] [INFO] Using worker: sync
[2021-01-22 15:11:38 +1000] [19583] [INFO] Booting worker with pid: 19583
[2021-01-22 15:11:38 +1000] [19584] [INFO] Booting worker with pid: 19584
[2021-01-22 15:11:38 +1000] [19585] [INFO] Booting worker with pid: 19585
[2021-01-22 15:14:53 +1000] [19585] [INFO] Worker exiting (pid: 19585)
[2021-01-22 15:14:53 +1000] [19583] [INFO] Worker exiting (pid: 19583)
[2021-01-22 15:14:53 +1000] [19584] [INFO] Worker exiting (pid: 19584)
[2021-01-22 15:14:54 +1000] [19566] [INFO] Handling signal: term
[2021-01-22 15:14:57 +1000] [19566] [INFO] Shutting down: Master
[2021-01-22 15:15:37 +1000] [471] [INFO] Starting gunicorn 20.0.4
[2021-01-22 15:15:37 +1000] [471] [INFO] Listening at: unix:/run/gunicorn.sock (471)
[2021-01-22 15:15:37 +1000] [471] [INFO] Using worker: sync
[2021-01-22 15:15:37 +1000] [901] [INFO] Booting worker with pid: 901
[2021-01-22 15:15:37 +1000] [907] [INFO] Booting worker with pid: 907
[2021-01-22 15:15:37 +1000] [908] [INFO] Booting worker with pid: 908
[2021-01-22 15:24:36 +1000] [471] [INFO] Handling signal: term
[2021-01-22 15:24:36 +1000] [908] [INFO] Worker exiting (pid: 908)
[2021-01-22 15:24:36 +1000] [901] [INFO] Worker exiting (pid: 901)
[2021-01-22 15:24:36 +1000] [907] [INFO] Worker exiting (pid: 907)
[2021-01-22 15:24:37 +1000] [471] [INFO] Shutting down: Master
[2021-01-22 15:24:43 +1000] [3021] [INFO] Starting gunicorn 20.0.4
[2021-01-22 15:24:43 +1000] [3021] [INFO] Listening at: unix:/run/gunicorn.sock (3021)
[2021-01-22 15:24:43 +1000] [3021] [INFO] Using worker: sync
[2021-01-22 15:24:43 +1000] [3036] [INFO] Booting worker with pid: 3036
[2021-01-22 15:24:43 +1000] [3040] [INFO] Booting worker with pid: 3040
[2021-01-22 15:24:43 +1000] [3041] [INFO] Booting worker with pid: 3041
[2021-01-26 13:32:24 +1000] [3041] [INFO] Worker exiting (pid: 3041)
[2021-01-26 13:32:24 +1000] [3040] [INFO] Worker exiting (pid: 3040)
[2021-01-26 13:32:24 +1000] [3021] [INFO] Handling signal: term
[2021-01-26 13:32:24 +1000] [3036] [INFO] Worker exiting (pid: 3036)
[2021-01-26 13:32:25 +1000] [3021] [INFO] Shutting down: Master
[2021-01-26 13:32:29 +1000] [21305] [INFO] Starting gunicorn 20.0.4
[2021-01-26 13:32:29 +1000] [21305] [INFO] Listening at: unix:/run/gunicorn.sock (21305)
[2021-01-26 13:32:29 +1000] [21305] [INFO] Using worker: sync
[2021-01-26 13:32:29 +1000] [21319] [INFO] Booting worker with pid: 21319
[2021-01-26 13:32:30 +1000] [21320] [INFO] Booting worker with pid: 21320
[2021-01-26 13:32:30 +1000] [21321] [INFO] Booting worker with pid: 21321
[2021-02-02 09:48:27 +1000] [21319] [INFO] Worker exiting (pid: 21319)
[2021-02-02 09:48:26 +1000] [21305] [INFO] Handling signal: term
[2021-02-02 09:48:27 +1000] [21320] [INFO] Worker exiting (pid: 21320)
[2021-02-02 09:48:27 +1000] [21321] [INFO] Worker exiting (pid: 21321)
[2021-02-02 09:48:27 +1000] [21305] [INFO] Shutting down: Master
[2021-02-02 09:48:32 +1000] [30424] [INFO] Starting gunicorn 20.0.4
[2021-02-02 09:48:32 +1000] [30424] [INFO] Listening at: unix:/run/gunicorn.sock (30424)
[2021-02-02 09:48:32 +1000] [30424] [INFO] Using worker: sync
[2021-02-02 09:48:32 +1000] [30438] [INFO] Booting worker with pid: 30438
[2021-02-02 09:48:32 +1000] [30439] [INFO] Booting worker with pid: 30439
[2021-02-02 09:48:32 +1000] [30440] [INFO] Booting worker with pid: 30440
[2021-02-02 10:07:09 +1000] [30424] [INFO] Handling signal: term
[2021-02-02 10:07:09 +1000] [30440] [INFO] Worker exiting (pid: 30440)
[2021-02-02 10:07:09 +1000] [30439] [INFO] Worker exiting (pid: 30439)
[2021-02-02 10:07:09 +1000] [30438] [INFO] Worker exiting (pid: 30438)
[2021-02-02 10:07:10 +1000] [30424] [INFO] Shutting down: Master
[2021-02-02 10:07:14 +1000] [880] [INFO] Starting gunicorn 20.0.4
[2021-02-02 10:07:14 +1000] [880] [INFO] Listening at: unix:/run/gunicorn.sock (880)
[2021-02-02 10:07:14 +1000] [880] [INFO] Using worker: sync
[2021-02-02 10:07:14 +1000] [896] [INFO] Booting worker with pid: 896
[2021-02-02 10:07:14 +1000] [900] [INFO] Booting worker with pid: 900
[2021-02-02 10:07:14 +1000] [901] [INFO] Booting worker with pid: 901
[2021-02-02 10:14:17 +1000] [880] [INFO] Handling signal: term
[2021-02-02 10:14:17 +1000] [901] [INFO] Worker exiting (pid: 901)
[2021-02-02 10:14:17 +1000] [900] [INFO] Worker exiting (pid: 900)
[2021-02-02 10:14:17 +1000] [896] [INFO] Worker exiting (pid: 896)
[2021-02-02 10:14:18 +1000] [880] [INFO] Shutting down: Master
[2021-02-02 10:14:21 +1000] [1954] [INFO] Starting gunicorn 20.0.4
[2021-02-02 10:14:21 +1000] [1954] [INFO] Listening at: unix:/run/gunicorn.sock (1954)
[2021-02-02 10:14:21 +1000] [1954] [INFO] Using worker: sync
[2021-02-02 10:14:21 +1000] [1969] [INFO] Booting worker with pid: 1969
[2021-02-02 10:14:21 +1000] [1970] [INFO] Booting worker with pid: 1970
[2021-02-02 10:14:21 +1000] [1971] [INFO] Booting worker with pid: 1971
[2021-02-02 10:24:26 +1000] [1954] [INFO] Handling signal: term
[2021-02-02 10:24:26 +1000] [1969] [INFO] Worker exiting (pid: 1969)
[2021-02-02 10:24:26 +1000] [1971] [INFO] Worker exiting (pid: 1971)
[2021-02-02 10:24:26 +1000] [1970] [INFO] Worker exiting (pid: 1970)
[2021-02-02 10:24:26 +1000] [1954] [INFO] Shutting down: Master
[2021-02-02 10:24:32 +1000] [3413] [INFO] Starting gunicorn 20.0.4
[2021-02-02 10:24:32 +1000] [3413] [INFO] Listening at: unix:/run/gunicorn.sock (3413)
[2021-02-02 10:24:32 +1000] [3413] [INFO] Using worker: sync
[2021-02-02 10:24:32 +1000] [3428] [INFO] Booting worker with pid: 3428
[2021-02-02 10:24:32 +1000] [3429] [INFO] Booting worker with pid: 3429
[2021-02-02 10:24:32 +1000] [3430] [INFO] Booting worker with pid: 3430
[2021-02-02 10:27:40 +1000] [3413] [INFO] Handling signal: term
[2021-02-02 10:27:40 +1000] [3430] [INFO] Worker exiting (pid: 3430)
[2021-02-02 10:27:40 +1000] [3428] [INFO] Worker exiting (pid: 3428)
[2021-02-02 10:27:40 +1000] [3429] [INFO] Worker exiting (pid: 3429)
[2021-02-02 10:27:40 +1000] [3413] [INFO] Shutting down: Master
[2021-02-02 10:27:41 +1000] [4501] [INFO] Starting gunicorn 20.0.4
[2021-02-02 10:27:41 +1000] [4501] [INFO] Listening at: unix:/run/gunicorn.sock (4501)
[2021-02-02 10:27:41 +1000] [4501] [INFO] Using worker: sync
[2021-02-02 10:27:41 +1000] [4518] [INFO] Booting worker with pid: 4518
[2021-02-02 10:27:41 +1000] [4520] [INFO] Booting worker with pid: 4520
[2021-02-02 10:27:41 +1000] [4519] [INFO] Booting worker with pid: 4519
[2021-02-02 10:28:03 +1000] [4520] [ERROR] Error handling request /sitemap.xml
Traceback (most recent call last):
  File "/home/debian/.venv/ytpdf/lib/python3.7/site-packages/django/core/handlers/exception.py", line 47, in inner
    response = get_response(request)
  File "/home/debian/.venv/ytpdf/lib/python3.7/site-packages/django/utils/deprecation.py", line 113, in __call__
    response = self.process_request(request)
  File "/home/debian/.venv/ytpdf/lib/python3.7/site-packages/django/middleware/common.py", line 53, in process_request
    if self.should_redirect_with_slash(request):
  File "/home/debian/.venv/ytpdf/lib/python3.7/site-packages/django/middleware/common.py", line 71, in should_redirect_with_slash
    not is_valid_path(request.path_info, urlconf) and
  File "/home/debian/.venv/ytpdf/lib/python3.7/site-packages/django/urls/base.py", line 154, in is_valid_path
    resolve(path, urlconf)
  File "/home/debian/.venv/ytpdf/lib/python3.7/site-packages/django/urls/base.py", line 25, in resolve
    return get_resolver(urlconf).resolve(path)
  File "/home/debian/.venv/ytpdf/lib/python3.7/site-packages/django/urls/resolvers.py", line 545, in resolve
    for pattern in self.url_patterns:
  File "/home/debian/.venv/ytpdf/lib/python3.7/site-packages/django/utils/functional.py", line 48, in __get__
    res = instance.__dict__[self.name] = self.func(instance)
  File "/home/debian/.venv/ytpdf/lib/python3.7/site-packages/django/urls/resolvers.py", line 589, in url_patterns
    patterns = getattr(self.urlconf_module, "urlpatterns", self.urlconf_module)
  File "/home/debian/.venv/ytpdf/lib/python3.7/site-packages/django/utils/functional.py", line 48, in __get__
    res = instance.__dict__[self.name] = self.func(instance)
  File "/home/debian/.venv/ytpdf/lib/python3.7/site-packages/django/urls/resolvers.py", line 582, in urlconf_module
    return import_module(self.urlconf_name)
  File "/usr/lib/python3.7/importlib/__init__.py", line 127, in import_module
    return _bootstrap._gcd_import(name[level:], package, level)
  File "<frozen importlib._bootstrap>", line 1006, in _gcd_import
  File "<frozen importlib._bootstrap>", line 983, in _find_and_load
  File "<frozen importlib._bootstrap>", line 967, in _find_and_load_unlocked
  File "<frozen importlib._bootstrap>", line 677, in _load_unlocked
  File "<frozen importlib._bootstrap_external>", line 728, in exec_module
  File "<frozen importlib._bootstrap>", line 219, in _call_with_frames_removed
  File "/home/debian/Projects/DJANGO_PROJ/media_utils/media_utils/urls.py", line 21, in <module>
    from . import view
ImportError: cannot import name 'view' from 'media_utils' (/home/debian/Projects/DJANGO_PROJ/media_utils/media_utils/__init__.py)

During handling of the above exception, another exception occurred:

Traceback (most recent call last):
  File "/home/debian/.venv/ytpdf/lib/python3.7/site-packages/django/core/handlers/exception.py", line 47, in inner
    response = get_response(request)
  File "/home/debian/.venv/ytpdf/lib/python3.7/site-packages/django/utils/deprecation.py", line 114, in __call__
    response = response or self.get_response(request)
  File "/home/debian/.venv/ytpdf/lib/python3.7/site-packages/django/core/handlers/exception.py", line 49, in inner
    response = response_for_exception(request, exc)
  File "/home/debian/.venv/ytpdf/lib/python3.7/site-packages/django/core/handlers/exception.py", line 103, in response_for_exception
    response = handle_uncaught_exception(request, get_resolver(get_urlconf()), sys.exc_info())
  File "/home/debian/.venv/ytpdf/lib/python3.7/site-packages/django/core/handlers/exception.py", line 141, in handle_uncaught_exception
    callback, param_dict = resolver.resolve_error_handler(500)
  File "/home/debian/.venv/ytpdf/lib/python3.7/site-packages/django/urls/resolvers.py", line 602, in resolve_error_handler
    callback = getattr(self.urlconf_module, 'handler%s' % view_type, None)
  File "/home/debian/.venv/ytpdf/lib/python3.7/site-packages/django/utils/functional.py", line 48, in __get__
    res = instance.__dict__[self.name] = self.func(instance)
  File "/home/debian/.venv/ytpdf/lib/python3.7/site-packages/django/urls/resolvers.py", line 582, in urlconf_module
    return import_module(self.urlconf_name)
  File "/usr/lib/python3.7/importlib/__init__.py", line 127, in import_module
    return _bootstrap._gcd_import(name[level:], package, level)
  File "<frozen importlib._bootstrap>", line 1006, in _gcd_import
  File "<frozen importlib._bootstrap>", line 983, in _find_and_load
  File "<frozen importlib._bootstrap>", line 967, in _find_and_load_unlocked
  File "<frozen importlib._bootstrap>", line 677, in _load_unlocked
  File "<frozen importlib._bootstrap_external>", line 728, in exec_module
  File "<frozen importlib._bootstrap>", line 219, in _call_with_frames_removed
  File "/home/debian/Projects/DJANGO_PROJ/media_utils/media_utils/urls.py", line 21, in <module>
    from . import view
ImportError: cannot import name 'view' from 'media_utils' (/home/debian/Projects/DJANGO_PROJ/media_utils/media_utils/__init__.py)

During handling of the above exception, another exception occurred:

Traceback (most recent call last):
  File "/home/debian/.venv/ytpdf/lib/python3.7/site-packages/django/core/handlers/exception.py", line 47, in inner
    response = get_response(request)
  File "/home/debian/.venv/ytpdf/lib/python3.7/site-packages/django/utils/deprecation.py", line 114, in __call__
    response = response or self.get_response(request)
  File "/home/debian/.venv/ytpdf/lib/python3.7/site-packages/django/core/handlers/exception.py", line 49, in inner
    response = response_for_exception(request, exc)
  File "/home/debian/.venv/ytpdf/lib/python3.7/site-packages/django/core/handlers/exception.py", line 103, in response_for_exception
    response = handle_uncaught_exception(request, get_resolver(get_urlconf()), sys.exc_info())
  File "/home/debian/.venv/ytpdf/lib/python3.7/site-packages/django/core/handlers/exception.py", line 141, in handle_uncaught_exception
    callback, param_dict = resolver.resolve_error_handler(500)
  File "/home/debian/.venv/ytpdf/lib/python3.7/site-packages/django/urls/resolvers.py", line 602, in resolve_error_handler
    callback = getattr(self.urlconf_module, 'handler%s' % view_type, None)
  File "/home/debian/.venv/ytpdf/lib/python3.7/site-packages/django/utils/functional.py", line 48, in __get__
    res = instance.__dict__[self.name] = self.func(instance)
  File "/home/debian/.venv/ytpdf/lib/python3.7/site-packages/django/urls/resolvers.py", line 582, in urlconf_module
    return import_module(self.urlconf_name)
  File "/usr/lib/python3.7/importlib/__init__.py", line 127, in import_module
    return _bootstrap._gcd_import(name[level:], package, level)
  File "<frozen importlib._bootstrap>", line 1006, in _gcd_import
  File "<frozen importlib._bootstrap>", line 983, in _find_and_load
  File "<frozen importlib._bootstrap>", line 967, in _find_and_load_unlocked
  File "<frozen importlib._bootstrap>", line 677, in _load_unlocked
  File "<frozen importlib._bootstrap_external>", line 728, in exec_module
  File "<frozen importlib._bootstrap>", line 219, in _call_with_frames_removed
  File "/home/debian/Projects/DJANGO_PROJ/media_utils/media_utils/urls.py", line 21, in <module>
    from . import view
ImportError: cannot import name 'view' from 'media_utils' (/home/debian/Projects/DJANGO_PROJ/media_utils/media_utils/__init__.py)

During handling of the above exception, another exception occurred:

Traceback (most recent call last):
  File "/home/debian/.venv/ytpdf/lib/python3.7/site-packages/gunicorn/workers/sync.py", line 134, in handle
    self.handle_request(listener, req, client, addr)
  File "/home/debian/.venv/ytpdf/lib/python3.7/site-packages/gunicorn/workers/sync.py", line 175, in handle_request
    respiter = self.wsgi(environ, resp.start_response)
  File "/home/debian/.venv/ytpdf/lib/python3.7/site-packages/django/core/handlers/wsgi.py", line 133, in __call__
    response = self.get_response(request)
  File "/home/debian/.venv/ytpdf/lib/python3.7/site-packages/django/core/handlers/base.py", line 128, in get_response
    response = self._middleware_chain(request)
  File "/home/debian/.venv/ytpdf/lib/python3.7/site-packages/django/core/handlers/exception.py", line 49, in inner
    response = response_for_exception(request, exc)
  File "/home/debian/.venv/ytpdf/lib/python3.7/site-packages/django/core/handlers/exception.py", line 103, in response_for_exception
    response = handle_uncaught_exception(request, get_resolver(get_urlconf()), sys.exc_info())
  File "/home/debian/.venv/ytpdf/lib/python3.7/site-packages/django/core/handlers/exception.py", line 141, in handle_uncaught_exception
    callback, param_dict = resolver.resolve_error_handler(500)
  File "/home/debian/.venv/ytpdf/lib/python3.7/site-packages/django/urls/resolvers.py", line 602, in resolve_error_handler
    callback = getattr(self.urlconf_module, 'handler%s' % view_type, None)
  File "/home/debian/.venv/ytpdf/lib/python3.7/site-packages/django/utils/functional.py", line 48, in __get__
    res = instance.__dict__[self.name] = self.func(instance)
  File "/home/debian/.venv/ytpdf/lib/python3.7/site-packages/django/urls/resolvers.py", line 582, in urlconf_module
    return import_module(self.urlconf_name)
  File "/usr/lib/python3.7/importlib/__init__.py", line 127, in import_module
    return _bootstrap._gcd_import(name[level:], package, level)
  File "<frozen importlib._bootstrap>", line 1006, in _gcd_import
  File "<frozen importlib._bootstrap>", line 983, in _find_and_load
  File "<frozen importlib._bootstrap>", line 967, in _find_and_load_unlocked
  File "<frozen importlib._bootstrap>", line 677, in _load_unlocked
  File "<frozen importlib._bootstrap_external>", line 728, in exec_module
  File "<frozen importlib._bootstrap>", line 219, in _call_with_frames_removed
  File "/home/debian/Projects/DJANGO_PROJ/media_utils/media_utils/urls.py", line 21, in <module>
    from . import view
ImportError: cannot import name 'view' from 'media_utils' (/home/debian/Projects/DJANGO_PROJ/media_utils/media_utils/__init__.py)
[2021-02-02 10:28:18 +1000] [4518] [ERROR] Error handling request /sitemap.xml
Traceback (most recent call last):
  File "/home/debian/.venv/ytpdf/lib/python3.7/site-packages/django/core/handlers/exception.py", line 47, in inner
    response = get_response(request)
  File "/home/debian/.venv/ytpdf/lib/python3.7/site-packages/django/utils/deprecation.py", line 113, in __call__
    response = self.process_request(request)
  File "/home/debian/.venv/ytpdf/lib/python3.7/site-packages/django/middleware/common.py", line 53, in process_request
    if self.should_redirect_with_slash(request):
  File "/home/debian/.venv/ytpdf/lib/python3.7/site-packages/django/middleware/common.py", line 71, in should_redirect_with_slash
    not is_valid_path(request.path_info, urlconf) and
  File "/home/debian/.venv/ytpdf/lib/python3.7/site-packages/django/urls/base.py", line 154, in is_valid_path
    resolve(path, urlconf)
  File "/home/debian/.venv/ytpdf/lib/python3.7/site-packages/django/urls/base.py", line 25, in resolve
    return get_resolver(urlconf).resolve(path)
  File "/home/debian/.venv/ytpdf/lib/python3.7/site-packages/django/urls/resolvers.py", line 545, in resolve
    for pattern in self.url_patterns:
  File "/home/debian/.venv/ytpdf/lib/python3.7/site-packages/django/utils/functional.py", line 48, in __get__
    res = instance.__dict__[self.name] = self.func(instance)
  File "/home/debian/.venv/ytpdf/lib/python3.7/site-packages/django/urls/resolvers.py", line 589, in url_patterns
    patterns = getattr(self.urlconf_module, "urlpatterns", self.urlconf_module)
  File "/home/debian/.venv/ytpdf/lib/python3.7/site-packages/django/utils/functional.py", line 48, in __get__
    res = instance.__dict__[self.name] = self.func(instance)
  File "/home/debian/.venv/ytpdf/lib/python3.7/site-packages/django/urls/resolvers.py", line 582, in urlconf_module
    return import_module(self.urlconf_name)
  File "/usr/lib/python3.7/importlib/__init__.py", line 127, in import_module
    return _bootstrap._gcd_import(name[level:], package, level)
  File "<frozen importlib._bootstrap>", line 1006, in _gcd_import
  File "<frozen importlib._bootstrap>", line 983, in _find_and_load
  File "<frozen importlib._bootstrap>", line 967, in _find_and_load_unlocked
  File "<frozen importlib._bootstrap>", line 677, in _load_unlocked
  File "<frozen importlib._bootstrap_external>", line 728, in exec_module
  File "<frozen importlib._bootstrap>", line 219, in _call_with_frames_removed
  File "/home/debian/Projects/DJANGO_PROJ/media_utils/media_utils/urls.py", line 21, in <module>
    from . import view
ImportError: cannot import name 'view' from 'media_utils' (/home/debian/Projects/DJANGO_PROJ/media_utils/media_utils/__init__.py)

During handling of the above exception, another exception occurred:

Traceback (most recent call last):
  File "/home/debian/.venv/ytpdf/lib/python3.7/site-packages/django/core/handlers/exception.py", line 47, in inner
    response = get_response(request)
  File "/home/debian/.venv/ytpdf/lib/python3.7/site-packages/django/utils/deprecation.py", line 114, in __call__
    response = response or self.get_response(request)
  File "/home/debian/.venv/ytpdf/lib/python3.7/site-packages/django/core/handlers/exception.py", line 49, in inner
    response = response_for_exception(request, exc)
  File "/home/debian/.venv/ytpdf/lib/python3.7/site-packages/django/core/handlers/exception.py", line 103, in response_for_exception
    response = handle_uncaught_exception(request, get_resolver(get_urlconf()), sys.exc_info())
  File "/home/debian/.venv/ytpdf/lib/python3.7/site-packages/django/core/handlers/exception.py", line 141, in handle_uncaught_exception
    callback, param_dict = resolver.resolve_error_handler(500)
  File "/home/debian/.venv/ytpdf/lib/python3.7/site-packages/django/urls/resolvers.py", line 602, in resolve_error_handler
    callback = getattr(self.urlconf_module, 'handler%s' % view_type, None)
  File "/home/debian/.venv/ytpdf/lib/python3.7/site-packages/django/utils/functional.py", line 48, in __get__
    res = instance.__dict__[self.name] = self.func(instance)
  File "/home/debian/.venv/ytpdf/lib/python3.7/site-packages/django/urls/resolvers.py", line 582, in urlconf_module
    return import_module(self.urlconf_name)
  File "/usr/lib/python3.7/importlib/__init__.py", line 127, in import_module
    return _bootstrap._gcd_import(name[level:], package, level)
  File "<frozen importlib._bootstrap>", line 1006, in _gcd_import
  File "<frozen importlib._bootstrap>", line 983, in _find_and_load
  File "<frozen importlib._bootstrap>", line 967, in _find_and_load_unlocked
  File "<frozen importlib._bootstrap>", line 677, in _load_unlocked
  File "<frozen importlib._bootstrap_external>", line 728, in exec_module
  File "<frozen importlib._bootstrap>", line 219, in _call_with_frames_removed
  File "/home/debian/Projects/DJANGO_PROJ/media_utils/media_utils/urls.py", line 21, in <module>
    from . import view
ImportError: cannot import name 'view' from 'media_utils' (/home/debian/Projects/DJANGO_PROJ/media_utils/media_utils/__init__.py)

During handling of the above exception, another exception occurred:

Traceback (most recent call last):
  File "/home/debian/.venv/ytpdf/lib/python3.7/site-packages/django/core/handlers/exception.py", line 47, in inner
    response = get_response(request)
  File "/home/debian/.venv/ytpdf/lib/python3.7/site-packages/django/utils/deprecation.py", line 114, in __call__
    response = response or self.get_response(request)
  File "/home/debian/.venv/ytpdf/lib/python3.7/site-packages/django/core/handlers/exception.py", line 49, in inner
    response = response_for_exception(request, exc)
  File "/home/debian/.venv/ytpdf/lib/python3.7/site-packages/django/core/handlers/exception.py", line 103, in response_for_exception
    response = handle_uncaught_exception(request, get_resolver(get_urlconf()), sys.exc_info())
  File "/home/debian/.venv/ytpdf/lib/python3.7/site-packages/django/core/handlers/exception.py", line 141, in handle_uncaught_exception
    callback, param_dict = resolver.resolve_error_handler(500)
  File "/home/debian/.venv/ytpdf/lib/python3.7/site-packages/django/urls/resolvers.py", line 602, in resolve_error_handler
    callback = getattr(self.urlconf_module, 'handler%s' % view_type, None)
  File "/home/debian/.venv/ytpdf/lib/python3.7/site-packages/django/utils/functional.py", line 48, in __get__
    res = instance.__dict__[self.name] = self.func(instance)
  File "/home/debian/.venv/ytpdf/lib/python3.7/site-packages/django/urls/resolvers.py", line 582, in urlconf_module
    return import_module(self.urlconf_name)
  File "/usr/lib/python3.7/importlib/__init__.py", line 127, in import_module
    return _bootstrap._gcd_import(name[level:], package, level)
  File "<frozen importlib._bootstrap>", line 1006, in _gcd_import
  File "<frozen importlib._bootstrap>", line 983, in _find_and_load
  File "<frozen importlib._bootstrap>", line 967, in _find_and_load_unlocked
  File "<frozen importlib._bootstrap>", line 677, in _load_unlocked
  File "<frozen importlib._bootstrap_external>", line 728, in exec_module
  File "<frozen importlib._bootstrap>", line 219, in _call_with_frames_removed
  File "/home/debian/Projects/DJANGO_PROJ/media_utils/media_utils/urls.py", line 21, in <module>
    from . import view
ImportError: cannot import name 'view' from 'media_utils' (/home/debian/Projects/DJANGO_PROJ/media_utils/media_utils/__init__.py)

During handling of the above exception, another exception occurred:

Traceback (most recent call last):
  File "/home/debian/.venv/ytpdf/lib/python3.7/site-packages/gunicorn/workers/sync.py", line 134, in handle
    self.handle_request(listener, req, client, addr)
  File "/home/debian/.venv/ytpdf/lib/python3.7/site-packages/gunicorn/workers/sync.py", line 175, in handle_request
    respiter = self.wsgi(environ, resp.start_response)
  File "/home/debian/.venv/ytpdf/lib/python3.7/site-packages/django/core/handlers/wsgi.py", line 133, in __call__
    response = self.get_response(request)
  File "/home/debian/.venv/ytpdf/lib/python3.7/site-packages/django/core/handlers/base.py", line 128, in get_response
    response = self._middleware_chain(request)
  File "/home/debian/.venv/ytpdf/lib/python3.7/site-packages/django/core/handlers/exception.py", line 49, in inner
    response = response_for_exception(request, exc)
  File "/home/debian/.venv/ytpdf/lib/python3.7/site-packages/django/core/handlers/exception.py", line 103, in response_for_exception
    response = handle_uncaught_exception(request, get_resolver(get_urlconf()), sys.exc_info())
  File "/home/debian/.venv/ytpdf/lib/python3.7/site-packages/django/core/handlers/exception.py", line 141, in handle_uncaught_exception
    callback, param_dict = resolver.resolve_error_handler(500)
  File "/home/debian/.venv/ytpdf/lib/python3.7/site-packages/django/urls/resolvers.py", line 602, in resolve_error_handler
    callback = getattr(self.urlconf_module, 'handler%s' % view_type, None)
  File "/home/debian/.venv/ytpdf/lib/python3.7/site-packages/django/utils/functional.py", line 48, in __get__
    res = instance.__dict__[self.name] = self.func(instance)
  File "/home/debian/.venv/ytpdf/lib/python3.7/site-packages/django/urls/resolvers.py", line 582, in urlconf_module
    return import_module(self.urlconf_name)
  File "/usr/lib/python3.7/importlib/__init__.py", line 127, in import_module
    return _bootstrap._gcd_import(name[level:], package, level)
  File "<frozen importlib._bootstrap>", line 1006, in _gcd_import
  File "<frozen importlib._bootstrap>", line 983, in _find_and_load
  File "<frozen importlib._bootstrap>", line 967, in _find_and_load_unlocked
  File "<frozen importlib._bootstrap>", line 677, in _load_unlocked
  File "<frozen importlib._bootstrap_external>", line 728, in exec_module
  File "<frozen importlib._bootstrap>", line 219, in _call_with_frames_removed
  File "/home/debian/Projects/DJANGO_PROJ/media_utils/media_utils/urls.py", line 21, in <module>
    from . import view
ImportError: cannot import name 'view' from 'media_utils' (/home/debian/Projects/DJANGO_PROJ/media_utils/media_utils/__init__.py)
[2021-02-02 10:28:19 +1000] [4519] [ERROR] Error handling request /sitemap.xml
Traceback (most recent call last):
  File "/home/debian/.venv/ytpdf/lib/python3.7/site-packages/django/core/handlers/exception.py", line 47, in inner
    response = get_response(request)
  File "/home/debian/.venv/ytpdf/lib/python3.7/site-packages/django/utils/deprecation.py", line 113, in __call__
    response = self.process_request(request)
  File "/home/debian/.venv/ytpdf/lib/python3.7/site-packages/django/middleware/common.py", line 53, in process_request
    if self.should_redirect_with_slash(request):
  File "/home/debian/.venv/ytpdf/lib/python3.7/site-packages/django/middleware/common.py", line 71, in should_redirect_with_slash
    not is_valid_path(request.path_info, urlconf) and
  File "/home/debian/.venv/ytpdf/lib/python3.7/site-packages/django/urls/base.py", line 154, in is_valid_path
    resolve(path, urlconf)
  File "/home/debian/.venv/ytpdf/lib/python3.7/site-packages/django/urls/base.py", line 25, in resolve
    return get_resolver(urlconf).resolve(path)
  File "/home/debian/.venv/ytpdf/lib/python3.7/site-packages/django/urls/resolvers.py", line 545, in resolve
    for pattern in self.url_patterns:
  File "/home/debian/.venv/ytpdf/lib/python3.7/site-packages/django/utils/functional.py", line 48, in __get__
    res = instance.__dict__[self.name] = self.func(instance)
  File "/home/debian/.venv/ytpdf/lib/python3.7/site-packages/django/urls/resolvers.py", line 589, in url_patterns
    patterns = getattr(self.urlconf_module, "urlpatterns", self.urlconf_module)
  File "/home/debian/.venv/ytpdf/lib/python3.7/site-packages/django/utils/functional.py", line 48, in __get__
    res = instance.__dict__[self.name] = self.func(instance)
  File "/home/debian/.venv/ytpdf/lib/python3.7/site-packages/django/urls/resolvers.py", line 582, in urlconf_module
    return import_module(self.urlconf_name)
  File "/usr/lib/python3.7/importlib/__init__.py", line 127, in import_module
    return _bootstrap._gcd_import(name[level:], package, level)
  File "<frozen importlib._bootstrap>", line 1006, in _gcd_import
  File "<frozen importlib._bootstrap>", line 983, in _find_and_load
  File "<frozen importlib._bootstrap>", line 967, in _find_and_load_unlocked
  File "<frozen importlib._bootstrap>", line 677, in _load_unlocked
  File "<frozen importlib._bootstrap_external>", line 728, in exec_module
  File "<frozen importlib._bootstrap>", line 219, in _call_with_frames_removed
  File "/home/debian/Projects/DJANGO_PROJ/media_utils/media_utils/urls.py", line 21, in <module>
    from . import view
ImportError: cannot import name 'view' from 'media_utils' (/home/debian/Projects/DJANGO_PROJ/media_utils/media_utils/__init__.py)

During handling of the above exception, another exception occurred:

Traceback (most recent call last):
  File "/home/debian/.venv/ytpdf/lib/python3.7/site-packages/django/core/handlers/exception.py", line 47, in inner
    response = get_response(request)
  File "/home/debian/.venv/ytpdf/lib/python3.7/site-packages/django/utils/deprecation.py", line 114, in __call__
    response = response or self.get_response(request)
  File "/home/debian/.venv/ytpdf/lib/python3.7/site-packages/django/core/handlers/exception.py", line 49, in inner
    response = response_for_exception(request, exc)
  File "/home/debian/.venv/ytpdf/lib/python3.7/site-packages/django/core/handlers/exception.py", line 103, in response_for_exception
    response = handle_uncaught_exception(request, get_resolver(get_urlconf()), sys.exc_info())
  File "/home/debian/.venv/ytpdf/lib/python3.7/site-packages/django/core/handlers/exception.py", line 141, in handle_uncaught_exception
    callback, param_dict = resolver.resolve_error_handler(500)
  File "/home/debian/.venv/ytpdf/lib/python3.7/site-packages/django/urls/resolvers.py", line 602, in resolve_error_handler
    callback = getattr(self.urlconf_module, 'handler%s' % view_type, None)
  File "/home/debian/.venv/ytpdf/lib/python3.7/site-packages/django/utils/functional.py", line 48, in __get__
    res = instance.__dict__[self.name] = self.func(instance)
  File "/home/debian/.venv/ytpdf/lib/python3.7/site-packages/django/urls/resolvers.py", line 582, in urlconf_module
    return import_module(self.urlconf_name)
  File "/usr/lib/python3.7/importlib/__init__.py", line 127, in import_module
    return _bootstrap._gcd_import(name[level:], package, level)
  File "<frozen importlib._bootstrap>", line 1006, in _gcd_import
  File "<frozen importlib._bootstrap>", line 983, in _find_and_load
  File "<frozen importlib._bootstrap>", line 967, in _find_and_load_unlocked
  File "<frozen importlib._bootstrap>", line 677, in _load_unlocked
  File "<frozen importlib._bootstrap_external>", line 728, in exec_module
  File "<frozen importlib._bootstrap>", line 219, in _call_with_frames_removed
  File "/home/debian/Projects/DJANGO_PROJ/media_utils/media_utils/urls.py", line 21, in <module>
    from . import view
ImportError: cannot import name 'view' from 'media_utils' (/home/debian/Projects/DJANGO_PROJ/media_utils/media_utils/__init__.py)

During handling of the above exception, another exception occurred:

Traceback (most recent call last):
  File "/home/debian/.venv/ytpdf/lib/python3.7/site-packages/django/core/handlers/exception.py", line 47, in inner
    response = get_response(request)
  File "/home/debian/.venv/ytpdf/lib/python3.7/site-packages/django/utils/deprecation.py", line 114, in __call__
    response = response or self.get_response(request)
  File "/home/debian/.venv/ytpdf/lib/python3.7/site-packages/django/core/handlers/exception.py", line 49, in inner
    response = response_for_exception(request, exc)
  File "/home/debian/.venv/ytpdf/lib/python3.7/site-packages/django/core/handlers/exception.py", line 103, in response_for_exception
    response = handle_uncaught_exception(request, get_resolver(get_urlconf()), sys.exc_info())
  File "/home/debian/.venv/ytpdf/lib/python3.7/site-packages/django/core/handlers/exception.py", line 141, in handle_uncaught_exception
    callback, param_dict = resolver.resolve_error_handler(500)
  File "/home/debian/.venv/ytpdf/lib/python3.7/site-packages/django/urls/resolvers.py", line 602, in resolve_error_handler
    callback = getattr(self.urlconf_module, 'handler%s' % view_type, None)
  File "/home/debian/.venv/ytpdf/lib/python3.7/site-packages/django/utils/functional.py", line 48, in __get__
    res = instance.__dict__[self.name] = self.func(instance)
  File "/home/debian/.venv/ytpdf/lib/python3.7/site-packages/django/urls/resolvers.py", line 582, in urlconf_module
    return import_module(self.urlconf_name)
  File "/usr/lib/python3.7/importlib/__init__.py", line 127, in import_module
    return _bootstrap._gcd_import(name[level:], package, level)
  File "<frozen importlib._bootstrap>", line 1006, in _gcd_import
  File "<frozen importlib._bootstrap>", line 983, in _find_and_load
  File "<frozen importlib._bootstrap>", line 967, in _find_and_load_unlocked
  File "<frozen importlib._bootstrap>", line 677, in _load_unlocked
  File "<frozen importlib._bootstrap_external>", line 728, in exec_module
  File "<frozen importlib._bootstrap>", line 219, in _call_with_frames_removed
  File "/home/debian/Projects/DJANGO_PROJ/media_utils/media_utils/urls.py", line 21, in <module>
    from . import view
ImportError: cannot import name 'view' from 'media_utils' (/home/debian/Projects/DJANGO_PROJ/media_utils/media_utils/__init__.py)

During handling of the above exception, another exception occurred:

Traceback (most recent call last):
  File "/home/debian/.venv/ytpdf/lib/python3.7/site-packages/gunicorn/workers/sync.py", line 134, in handle
    self.handle_request(listener, req, client, addr)
  File "/home/debian/.venv/ytpdf/lib/python3.7/site-packages/gunicorn/workers/sync.py", line 175, in handle_request
    respiter = self.wsgi(environ, resp.start_response)
  File "/home/debian/.venv/ytpdf/lib/python3.7/site-packages/django/core/handlers/wsgi.py", line 133, in __call__
    response = self.get_response(request)
  File "/home/debian/.venv/ytpdf/lib/python3.7/site-packages/django/core/handlers/base.py", line 128, in get_response
    response = self._middleware_chain(request)
  File "/home/debian/.venv/ytpdf/lib/python3.7/site-packages/django/core/handlers/exception.py", line 49, in inner
    response = response_for_exception(request, exc)
  File "/home/debian/.venv/ytpdf/lib/python3.7/site-packages/django/core/handlers/exception.py", line 103, in response_for_exception
    response = handle_uncaught_exception(request, get_resolver(get_urlconf()), sys.exc_info())
  File "/home/debian/.venv/ytpdf/lib/python3.7/site-packages/django/core/handlers/exception.py", line 141, in handle_uncaught_exception
    callback, param_dict = resolver.resolve_error_handler(500)
  File "/home/debian/.venv/ytpdf/lib/python3.7/site-packages/django/urls/resolvers.py", line 602, in resolve_error_handler
    callback = getattr(self.urlconf_module, 'handler%s' % view_type, None)
  File "/home/debian/.venv/ytpdf/lib/python3.7/site-packages/django/utils/functional.py", line 48, in __get__
    res = instance.__dict__[self.name] = self.func(instance)
  File "/home/debian/.venv/ytpdf/lib/python3.7/site-packages/django/urls/resolvers.py", line 582, in urlconf_module
    return import_module(self.urlconf_name)
  File "/usr/lib/python3.7/importlib/__init__.py", line 127, in import_module
    return _bootstrap._gcd_import(name[level:], package, level)
  File "<frozen importlib._bootstrap>", line 1006, in _gcd_import
  File "<frozen importlib._bootstrap>", line 983, in _find_and_load
  File "<frozen importlib._bootstrap>", line 967, in _find_and_load_unlocked
  File "<frozen importlib._bootstrap>", line 677, in _load_unlocked
  File "<frozen importlib._bootstrap_external>", line 728, in exec_module
  File "<frozen importlib._bootstrap>", line 219, in _call_with_frames_removed
  File "/home/debian/Projects/DJANGO_PROJ/media_utils/media_utils/urls.py", line 21, in <module>
    from . import view
ImportError: cannot import name 'view' from 'media_utils' (/home/debian/Projects/DJANGO_PROJ/media_utils/media_utils/__init__.py)
[2021-02-02 10:28:23 +1000] [4501] [INFO] Handling signal: term
[2021-02-02 10:28:23 +1000] [4518] [INFO] Worker exiting (pid: 4518)
[2021-02-02 10:28:23 +1000] [4520] [INFO] Worker exiting (pid: 4520)
[2021-02-02 10:28:23 +1000] [4519] [INFO] Worker exiting (pid: 4519)
[2021-02-02 10:28:23 +1000] [4501] [INFO] Shutting down: Master
[2021-02-02 10:28:24 +1000] [4797] [INFO] Starting gunicorn 20.0.4
[2021-02-02 10:28:24 +1000] [4797] [INFO] Listening at: unix:/run/gunicorn.sock (4797)
[2021-02-02 10:28:24 +1000] [4797] [INFO] Using worker: sync
[2021-02-02 10:28:24 +1000] [4811] [INFO] Booting worker with pid: 4811
[2021-02-02 10:28:24 +1000] [4812] [INFO] Booting worker with pid: 4812
[2021-02-02 10:28:24 +1000] [4816] [INFO] Booting worker with pid: 4816
[2021-02-02 10:28:49 +1000] [4797] [INFO] Handling signal: term
[2021-02-02 10:28:49 +1000] [4811] [INFO] Worker exiting (pid: 4811)
[2021-02-02 10:28:49 +1000] [4816] [INFO] Worker exiting (pid: 4816)
[2021-02-02 10:28:49 +1000] [4812] [INFO] Worker exiting (pid: 4812)
[2021-02-02 10:28:49 +1000] [4797] [INFO] Shutting down: Master
[2021-02-02 10:28:50 +1000] [4969] [INFO] Starting gunicorn 20.0.4
[2021-02-02 10:28:50 +1000] [4969] [INFO] Listening at: unix:/run/gunicorn.sock (4969)
[2021-02-02 10:28:50 +1000] [4969] [INFO] Using worker: sync
[2021-02-02 10:28:50 +1000] [4983] [INFO] Booting worker with pid: 4983
[2021-02-02 10:28:50 +1000] [4984] [INFO] Booting worker with pid: 4984
[2021-02-02 10:28:50 +1000] [4987] [INFO] Booting worker with pid: 4987
[2021-02-02 10:33:46 +1000] [4984] [INFO] Worker exiting (pid: 4984)
[2021-02-02 10:33:46 +1000] [4983] [INFO] Worker exiting (pid: 4983)
[2021-02-02 10:33:46 +1000] [4987] [INFO] Worker exiting (pid: 4987)
[2021-02-02 10:33:46 +1000] [4969] [INFO] Handling signal: term
[2021-02-02 10:33:46 +1000] [4969] [INFO] Shutting down: Master
[2021-02-02 10:33:47 +1000] [5604] [INFO] Starting gunicorn 20.0.4
[2021-02-02 10:33:47 +1000] [5604] [INFO] Listening at: unix:/run/gunicorn.sock (5604)
[2021-02-02 10:33:47 +1000] [5604] [INFO] Using worker: sync
[2021-02-02 10:33:47 +1000] [5619] [INFO] Booting worker with pid: 5619
[2021-02-02 10:33:47 +1000] [5620] [INFO] Booting worker with pid: 5620
[2021-02-02 10:33:47 +1000] [5621] [INFO] Booting worker with pid: 5621
[2021-02-02 10:34:37 +1000] [5604] [INFO] Handling signal: term
[2021-02-02 10:34:37 +1000] [5620] [INFO] Worker exiting (pid: 5620)
[2021-02-02 10:34:37 +1000] [5621] [INFO] Worker exiting (pid: 5621)
[2021-02-02 10:34:37 +1000] [5619] [INFO] Worker exiting (pid: 5619)
[2021-02-02 10:34:38 +1000] [5604] [INFO] Shutting down: Master
[2021-02-02 10:34:38 +1000] [5782] [INFO] Starting gunicorn 20.0.4
[2021-02-02 10:34:38 +1000] [5782] [INFO] Listening at: unix:/run/gunicorn.sock (5782)
[2021-02-02 10:34:38 +1000] [5782] [INFO] Using worker: sync
[2021-02-02 10:34:38 +1000] [5799] [INFO] Booting worker with pid: 5799
[2021-02-02 10:34:39 +1000] [5800] [INFO] Booting worker with pid: 5800
[2021-02-02 10:34:39 +1000] [5801] [INFO] Booting worker with pid: 5801
[2021-02-02 10:35:26 +1000] [5801] [INFO] Worker exiting (pid: 5801)
[2021-02-02 10:35:26 +1000] [5800] [INFO] Worker exiting (pid: 5800)
[2021-02-02 10:35:26 +1000] [5782] [INFO] Handling signal: term
[2021-02-02 10:35:26 +1000] [5799] [INFO] Worker exiting (pid: 5799)
[2021-02-02 10:35:26 +1000] [5782] [INFO] Shutting down: Master
[2021-02-02 10:35:27 +1000] [5957] [INFO] Starting gunicorn 20.0.4
[2021-02-02 10:35:27 +1000] [5957] [INFO] Listening at: unix:/run/gunicorn.sock (5957)
[2021-02-02 10:35:27 +1000] [5957] [INFO] Using worker: sync
[2021-02-02 10:35:27 +1000] [5971] [INFO] Booting worker with pid: 5971
[2021-02-02 10:35:27 +1000] [5972] [INFO] Booting worker with pid: 5972
[2021-02-02 10:35:27 +1000] [5973] [INFO] Booting worker with pid: 5973
[2021-02-02 10:36:29 +1000] [5972] [INFO] Worker exiting (pid: 5972)
[2021-02-02 10:36:29 +1000] [5973] [INFO] Worker exiting (pid: 5973)
[2021-02-02 10:36:29 +1000] [5971] [INFO] Worker exiting (pid: 5971)
[2021-02-02 10:36:29 +1000] [5957] [INFO] Handling signal: term
[2021-02-02 10:36:30 +1000] [5957] [INFO] Shutting down: Master
[2021-02-02 10:36:30 +1000] [6161] [INFO] Starting gunicorn 20.0.4
[2021-02-02 10:36:30 +1000] [6161] [INFO] Listening at: unix:/run/gunicorn.sock (6161)
[2021-02-02 10:36:30 +1000] [6161] [INFO] Using worker: sync
[2021-02-02 10:36:30 +1000] [6178] [INFO] Booting worker with pid: 6178
[2021-02-02 10:36:31 +1000] [6179] [INFO] Booting worker with pid: 6179
[2021-02-02 10:36:31 +1000] [6182] [INFO] Booting worker with pid: 6182
[2021-02-02 10:40:09 +1000] [6161] [INFO] Handling signal: term
[2021-02-02 10:40:09 +1000] [6179] [INFO] Worker exiting (pid: 6179)
[2021-02-02 10:40:09 +1000] [6182] [INFO] Worker exiting (pid: 6182)
[2021-02-02 10:40:09 +1000] [6178] [INFO] Worker exiting (pid: 6178)
[2021-02-02 10:40:10 +1000] [6161] [INFO] Shutting down: Master
[2021-02-02 10:40:11 +1000] [6736] [INFO] Starting gunicorn 20.0.4
[2021-02-02 10:40:11 +1000] [6736] [INFO] Listening at: unix:/run/gunicorn.sock (6736)
[2021-02-02 10:40:11 +1000] [6736] [INFO] Using worker: sync
[2021-02-02 10:40:11 +1000] [6754] [INFO] Booting worker with pid: 6754
[2021-02-02 10:40:11 +1000] [6755] [INFO] Booting worker with pid: 6755
[2021-02-02 10:40:11 +1000] [6756] [INFO] Booting worker with pid: 6756
[2021-02-02 10:50:30 +1000] [6754] [INFO] Worker exiting (pid: 6754)
[2021-02-02 10:50:30 +1000] [6756] [INFO] Worker exiting (pid: 6756)
[2021-02-02 10:50:30 +1000] [6755] [INFO] Worker exiting (pid: 6755)
[2021-02-02 10:50:30 +1000] [6736] [INFO] Handling signal: term
[2021-02-02 10:50:30 +1000] [6736] [INFO] Shutting down: Master
[2021-02-02 10:50:31 +1000] [8101] [INFO] Starting gunicorn 20.0.4
[2021-02-02 10:50:31 +1000] [8101] [INFO] Listening at: unix:/run/gunicorn.sock (8101)
[2021-02-02 10:50:31 +1000] [8101] [INFO] Using worker: sync
[2021-02-02 10:50:31 +1000] [8119] [INFO] Booting worker with pid: 8119
[2021-02-02 10:50:31 +1000] [8120] [INFO] Booting worker with pid: 8120
[2021-02-02 10:50:31 +1000] [8121] [INFO] Booting worker with pid: 8121
[2021-02-02 10:52:01 +1000] [8121] [INFO] Worker exiting (pid: 8121)
[2021-02-02 10:52:01 +1000] [8120] [INFO] Worker exiting (pid: 8120)
[2021-02-02 10:52:01 +1000] [8101] [INFO] Handling signal: term
[2021-02-02 10:52:01 +1000] [8119] [INFO] Worker exiting (pid: 8119)
[2021-02-02 10:52:02 +1000] [8101] [INFO] Shutting down: Master
[2021-02-02 10:52:03 +1000] [8364] [INFO] Starting gunicorn 20.0.4
[2021-02-02 10:52:03 +1000] [8364] [INFO] Listening at: unix:/run/gunicorn.sock (8364)
[2021-02-02 10:52:03 +1000] [8364] [INFO] Using worker: sync
[2021-02-02 10:52:03 +1000] [8381] [INFO] Booting worker with pid: 8381
[2021-02-02 10:52:03 +1000] [8382] [INFO] Booting worker with pid: 8382
[2021-02-02 10:52:03 +1000] [8383] [INFO] Booting worker with pid: 8383
[2021-02-02 11:00:00 +1000] [8382] [INFO] Worker exiting (pid: 8382)
[2021-02-02 11:00:00 +1000] [8383] [INFO] Worker exiting (pid: 8383)
[2021-02-02 11:00:00 +1000] [8381] [INFO] Worker exiting (pid: 8381)
[2021-02-02 11:00:00 +1000] [8364] [INFO] Handling signal: term
[2021-02-02 11:00:01 +1000] [8364] [INFO] Shutting down: Master
[2021-02-02 11:00:02 +1000] [9554] [INFO] Starting gunicorn 20.0.4
[2021-02-02 11:00:02 +1000] [9554] [INFO] Listening at: unix:/run/gunicorn.sock (9554)
[2021-02-02 11:00:02 +1000] [9554] [INFO] Using worker: sync
[2021-02-02 11:00:02 +1000] [9569] [INFO] Booting worker with pid: 9569
[2021-02-02 11:00:02 +1000] [9570] [INFO] Booting worker with pid: 9570
[2021-02-02 11:00:02 +1000] [9573] [INFO] Booting worker with pid: 9573
[2021-02-02 11:01:03 +1000] [9554] [INFO] Handling signal: term
[2021-02-02 11:01:03 +1000] [9573] [INFO] Worker exiting (pid: 9573)
[2021-02-02 11:01:03 +1000] [9569] [INFO] Worker exiting (pid: 9569)
[2021-02-02 11:01:03 +1000] [9570] [INFO] Worker exiting (pid: 9570)
[2021-02-02 11:01:03 +1000] [9554] [INFO] Shutting down: Master
[2021-02-02 11:01:04 +1000] [9889] [INFO] Starting gunicorn 20.0.4
[2021-02-02 11:01:04 +1000] [9889] [INFO] Listening at: unix:/run/gunicorn.sock (9889)
[2021-02-02 11:01:04 +1000] [9889] [INFO] Using worker: sync
[2021-02-02 11:01:04 +1000] [9904] [INFO] Booting worker with pid: 9904
[2021-02-02 11:01:04 +1000] [9905] [INFO] Booting worker with pid: 9905
[2021-02-02 11:01:04 +1000] [9908] [INFO] Booting worker with pid: 9908
[2021-02-02 11:02:55 +1000] [9889] [INFO] Handling signal: term
[2021-02-02 11:02:55 +1000] [9908] [INFO] Worker exiting (pid: 9908)
[2021-02-02 11:02:55 +1000] [9904] [INFO] Worker exiting (pid: 9904)
[2021-02-02 11:02:55 +1000] [9905] [INFO] Worker exiting (pid: 9905)
[2021-02-02 11:02:55 +1000] [9889] [INFO] Shutting down: Master
[2021-02-02 11:02:56 +1000] [10202] [INFO] Starting gunicorn 20.0.4
[2021-02-02 11:02:56 +1000] [10202] [INFO] Listening at: unix:/run/gunicorn.sock (10202)
[2021-02-02 11:02:56 +1000] [10202] [INFO] Using worker: sync
[2021-02-02 11:02:56 +1000] [10216] [INFO] Booting worker with pid: 10216
[2021-02-02 11:02:56 +1000] [10217] [INFO] Booting worker with pid: 10217
[2021-02-02 11:02:56 +1000] [10218] [INFO] Booting worker with pid: 10218
[2021-02-02 11:04:06 +1000] [10216] [INFO] Worker exiting (pid: 10216)
[2021-02-02 11:04:06 +1000] [10202] [INFO] Handling signal: term
[2021-02-02 11:04:06 +1000] [10218] [INFO] Worker exiting (pid: 10218)
[2021-02-02 11:04:06 +1000] [10217] [INFO] Worker exiting (pid: 10217)
[2021-02-02 11:04:06 +1000] [10202] [INFO] Shutting down: Master
[2021-02-02 11:04:07 +1000] [10433] [INFO] Starting gunicorn 20.0.4
[2021-02-02 11:04:07 +1000] [10433] [INFO] Listening at: unix:/run/gunicorn.sock (10433)
[2021-02-02 11:04:07 +1000] [10433] [INFO] Using worker: sync
[2021-02-02 11:04:07 +1000] [10450] [INFO] Booting worker with pid: 10450
[2021-02-02 11:04:07 +1000] [10452] [INFO] Booting worker with pid: 10452
[2021-02-02 11:04:07 +1000] [10451] [INFO] Booting worker with pid: 10451
[2021-02-02 11:15:26 +1000] [10433] [INFO] Handling signal: term
[2021-02-02 11:15:26 +1000] [10452] [INFO] Worker exiting (pid: 10452)
[2021-02-02 11:15:26 +1000] [10450] [INFO] Worker exiting (pid: 10450)
[2021-02-02 11:15:26 +1000] [10451] [INFO] Worker exiting (pid: 10451)
[2021-02-02 11:15:27 +1000] [10433] [INFO] Shutting down: Master
[2021-02-02 11:15:27 +1000] [11992] [INFO] Starting gunicorn 20.0.4
[2021-02-02 11:15:27 +1000] [11992] [INFO] Listening at: unix:/run/gunicorn.sock (11992)
[2021-02-02 11:15:27 +1000] [11992] [INFO] Using worker: sync
[2021-02-02 11:15:27 +1000] [12007] [INFO] Booting worker with pid: 12007
[2021-02-02 11:15:27 +1000] [12008] [INFO] Booting worker with pid: 12008
[2021-02-02 11:15:27 +1000] [12009] [INFO] Booting worker with pid: 12009
